Workbook

Sheet Como ler
A1: De-para entre a taxonomia de temas e o risk tracking corporativo
A3: O que este arquivo responde
A4: Dado um fato de mídia já classificado na taxonomia de três níveis, qual risco corporativo da Aegea ele materializa. A ligação é feita no nível do subtema, que é o nível em que a notícia é classificada.
A6: Fontes e datas de corte
A7: Taxonomia de temas: versão de três níveis fechada em 07/10/2026. 104 subtemas, 7 pilares.
A8: Risk tracking: 32 riscos em 8 clusters, com severidade validada pela Aegea em 07/10/2026. Severidade reproduzida como recebida, sem recálculo.
A9: Atribuição subtema para risco: premissa Peers, data de corte 08/10/2026. Não validada com a área de Riscos da Aegea. É isto que esta reunião precisa decidir.
A11: Regra de atribuição usada
A12: Cada subtema recebe um risco primário, que é o risco onde o dano se materializa, e não o risco de onde vem a narrativa. Exemplo: reajuste tarifário gera reação da comunidade, mas o dano se materializa no eixo Legal e Regulatório, porque o ato é regulatório e é lá que a empresa responde.
A13: O risco secundário registra a segunda leitura legítima do mesmo fato. Serve para discussão, não para contagem. Somar primário e secundário gera dupla contagem.
A14: Quatro subtemas ficam como Sem enquadramento. São narrativa institucional ou impacto positivo, sem risco corporativo correspondente. A ausência é deliberada, não é falha de mapeamento.
A16: Coluna de exemplo de notícia
... A29: Amarelo: preenchimento da Aegea na validação. Verde: exemplo com lastro na base de janeiro. Cinza: subtema sem enquadramento de risco.

Sheet Visão Fernanda
A1: Nível 1: Pilar reputacional | B1: Nível 2: Tema estratégico | C1: Nível 3: Subtema | D1: LSO | E1: Formato | F1: Detalhamento | G1: Pauta | H1: Campo de classificação da empresa | I1: To do Comunicação
A2: 1. Governança | B2: Governança corporativa | C2: Estrutura de governança / Conselho e comitês | D2: Credibilidade | E2: Notícias/Publicações | G2: Espontânea | H2: Concorrentes | I2: Definição de porta-vozes
A3: 1. Governança | B3: Governança corporativa | C3: Acionistas | D3: Credibilidade | E3: Comunicados | G3: Produzida | H3: Unidades Aegea | I3: Preenchimento planilha
A4: 1. Governança | B4: Contratos e Regulação | C4: Cumprimento contratual | D4: Legitimidade | E4: Entrevistas | G4: Provocada | I4: Validar taxonomia
A5: 1. Governança | B5: Contratos e Regulação | C5: Revisão e renovação de contratos | D5: Legitimidade | E5: Nota explicativa | G5: Publicidade | I5: Usuários
A6: 1. Governança | B6: Contratos e Regulação | C6: Reequilíbrio econômico-financeiro | D6: Legitimidade | I6: Reprisk
A7: 1. Governança | B7: Contratos e Regulação | C7: Segurança jurídica | D7: Legitimidade | I7: Porta vozes
A8: 1. Governança | B8: Contratos e Regulação | C8: Fiscalização regulatória | D8: Legitimidade
A9: 1. Governança | B9: Contratos e Regulação | C9: Multa e processos | D9: Credibilidade
A10: 1. Governança | B10: Integridade | C10: Ética e conduta | D10: Credibilidade
A11: 1. Governança | B11: Integridade | C11: Investigações e Acordo | D11: Credibilidade
A12: 1. Governança | B12: Integridade | C12: Controles internos / Prevenção à fraude e corrupção | D12: Credibilidade
A13: 1. Governança | B13: Integridade | C13: Demonstrações de resultados e auditoria | D13: Credibilidade
A14: 1. Governança | B14: Modelo de negócio | C14: Modelo Operacional Aegea | D14: Credibilidade
A15: 1. Governança | B15: Político-institucional | C15: Políticas públicas e setoriais | D15: Credibilidade
A16: 1. Governança | B16: Político-institucional | C16: Patrocínios | D16: Credibilidade
A17: 1. Governança | B17: Político-institucional | C17: Debate público versus privado | D17: Credibilidade
A18: 1. Governança | B18: Político-institucional | C18: Judicialização e CPIs | D18: Credibilidade
A19: 1. Governança | B19: Político-institucional | C19: Marco Legal do Saneamento
A20: 1. Governança | B20: Contratos e Regulação | C20: Agências reguladoras
A21: 1. Governança | B21: Político-institucional | C21: Agenda Associações (Politicas setoriais) | D21: Credibilidade
A22: 2. Eficiência Operacional e Qualidade | B22: Água Abastecimento | C22: Frequência, Continuidade | D22: Legitimidade
A23: 2. Eficiência Operacional e Qualidade | B23: Água Abastecimento | C23: Perdas, fraudes, furtos e ligações irregulares | D23: Legitimidade
A24: 2. Eficiência Operacional e Qualidade | B24: Água Abastecimento | C24: Rompimento de adutora | D24: Legitimidade
A25: 2. Eficiência Operacional e Qualidade | B25: Água Abastecimento | C25: Plano de contingência e redundância | D25: Legitimidade
A26: 2. Eficiência Operacional e Qualidade | B26: Água Abastecimento | C26: Informativo sobre abastecimento | D26: Legitimidade | E26: Talvez tirar, estava informativo
A27: 2. Eficiência Operacional e Qualidade | B27: Água Qualidade | C27: Gestão da qualidade da água | D27: Legitimidade
A28: 2. Eficiência Operacional e Qualidade | B28: Água Qualidade | C28: Monitoramento e controle de qualidade da água | D28: Legitimidade
A29: 2. Eficiência Operacional e Qualidade | B29: Água Qualidade | C29: Potabilidade | D29: Legitimidade
A30: 2. Eficiência Operacional e Qualidade | B30: Esgoto | C30: Rede e Coleta de esgoto | D30: Legitimidade
A31: 2. Eficiência Operacional e Qualidade | B31: Esgoto | C31: Tratamento de esgoto | D31: Legitimidade
A32: 2. Eficiência Operacional e Qualidade | B32: Esgoto | C32: Lançamento irregular e extravazamento | D32: Legitimidade
A33: 2. Eficiência Operacional e Qualidade | B33: Esgoto | C33: Balneabilidade | D33: Legitimidade
A34: 2. Eficiência Operacional e Qualidade | B34: Obras e intervenções | C34: Custos e eficiência | D34: Credibilidade
A35: 2. Eficiência Operacional e Qualidade | B35: Obras e intervenções | C35: Acidentes e danos a terceiros | D35: Credibilidade
A36: 2. Eficiência Operacional e Qualidade | B36: Obras e intervenções | C36: Expansão da rede | D36: Credibilidade
A37: 2. Eficiência Operacional e Qualidade | B37: Obras e intervenções | C37: Pavimentação e recomposição | D37: Credibilidade
A38: 2. Eficiência Operacional e Qualidade | B38: Obras e intervenções | C38: Manutenção, interdicções e transtornos urbanos | D38: Credibilidade
... A41: 2. Eficiência Operacional e Qualidade | B41: Atendimento ao cliente | C41: Órgãos de defesa ao cliente (Ouvidoria, Procon, Reclame Aqui, etc) | D41: Credibilidade
A42: 2. Eficiência Operacional e Qualidade | B42: Faturamento e cobrança | C42: Medição e leitura
...

Sheet De-para Risk tracking
A1: # | B1: Nível 1: Pilar reputacional | C1: Nível 2: Tema estratégico | D1: Nível 3: Subtema | E1: LSO | F1: Domínio de risco | G1: Risk tracking (risco primário) | H1: Severidade | I1: Risco secundário | J1: Por que esse de-para | K1: Exemplo de notícia que se enquadra no risco e no subtema | L1: Origem do exemplo | M1: Validação Aegea (concorda S/N) | N1: Ajuste proposto pela área
A2: 1 | B2: 1. Governança | C2: Governança corporativa | D2: Estrutura de governança / Conselho e comitês | E2: Credibilidade | F2: — | G2: Sem enquadramento | H2: — | J2: Narrativa institucional. Não existe risco corporativo equivalente entre os 32 clusters. A ausência é deliberada, não é lacuna de mapeamento. | K2: Não se aplica. Notícia negativa sobre conselho ou alta administração é registrada em Ética e conduta ou em Acionistas, que têm cluster de risco. | L2: —
A3: 2 | B3: 1. Governança | C3: Governança corporativa | D3: Acionistas | E3: Credibilidade | F3: Riscos Geopolíticos e Estratégicos | G3: Gestão de Portfólio e Estrutura de Capital | H3: Alto | I3: Integridade das Informações ao Mercado | J3: Movimento de composição acionária e de controle atinge primeiro a estrutura de capital e o portfólio, antes de qualquer outro eixo. | K3: Negociação de venda de participação de acionista relevante do grupo, com especulação de mudança de controle em veículo econômico. | L3: Exemplo típico (premissa Peers)
A4: 3 | B4: 1. Governança | C4: Contratos e Regulação | D4: Cumprimento contratual | E4: Legitimidade | F4: Riscos Geopolíticos e Estratégicos | G4: Legal e Regulatório | H4: Moderado | I4: Gestão de Contratos e Terceiros | J4: Descumprimento de contrato de concessão é evento regulatório, com sanção e risco de caducidade. O dano se materializa no eixo legal. | K4: Agência reguladora notifica a concessionária por não atingir metas de cobertura previstas no contrato, com abertura de processo sancionador. | L4: Exemplo típico (premissa Peers)
A5: 4 | B5: 1. Governança | C5: Contratos e Regulação | D5: Revisão e renovação de contratos | E5: Legitimidade | F5: Riscos Geopolíticos e Estratégicos | G5: Legal e Regulatório | H5: Moderado | I5: Assunção de novos negócios | J5: Revisão e prorrogação tramitam no poder concedente e no regulador, mesmo quando a motivação é comercial. | K5: Câmara municipal discute aditivo de prorrogação do contrato e vereadores pedem suspensão da assinatura. | L5: Exemplo típico (premissa Peers)
A6: 5 | B6: 1. Governança | C6: Contratos e Regulação | D6: Reequilíbrio econômico-financeiro | E6: Legitimidade | F6: Riscos Geopolíticos e Estratégicos | G6: Legal e Regulatório | H6: Moderado | I6: Contingências e Provisões | J6: Pleito de reequilíbrio é disputa regulatória, com desdobramento em provisão quando vira litígio. | K6: Prefeitura contesta publicamente o pleito de reequilíbrio apresentado pela concessionária e aciona a agência reguladora. | L6: Exemplo típico (premissa Peers)
A7: 6 | B7: 1. Governança | C7: Contratos e Regulação | D7: Segurança jurídica | E7: Legitimidade | F7: Riscos Geopolíticos e Estratégicos | G7: Legal e Regulatório | H7: Moderado | I7: Instabilidade Política / Econômica | J7: Estabilidade das regras do contrato. Tangencia instabilidade política quando a origem é troca de governo. | K7: Nova gestão municipal anuncia revisão do contrato de concessão assinado pela gestão anterior. | L7: Exemplo típico (premissa Peers)
A8: 7 | B8: 1. Governança | C8: Contratos e Regulação | D8: Fiscalização regulatória | E8: Legitimidade | F8: Riscos Geopolíticos e Estratégicos | G8: Legal e Regulatório | H8: Moderado | I8: Relações Institucionais e Governamentais | J8: Ato do regulador contra a empresa é risco legal. A relação institucional com a agência fica como leitura secundária. | K8: Agência reguladora abre fiscalização extraordinária após série de interrupções de abastecimento em município atendido. | L8: Exemplo típico (premissa Peers)
A9: 8 | B9: 1. Governança | C9: Contratos e Regulação | D9: Multa e processos | E9: Credibilidade | F9: Riscos com Finanças e Contabilidade | G9: Contingências e Provisões | H9: Moderado | I9: Legal e Regulatório | J9: Multa aplicada e processo em curso são passivo mensurável. Entram pelo eixo de contingência e provisão. | K9: Concessionária é multada pelo regulador por descumprimento de prazo de atendimento e recorre da decisão. | L9: Exemplo típico (premissa Peers)
A10: 9 | B10: 1. Governança | C10: Integridade | D10: Ética e conduta | E10: Credibilidade | F10: Riscos Geopolíticos e Estratégicos | G10: Práticas Ilegais ou Antiéticas | H10: Alto | J10: Conduta individual ou corporativa questionada. Núcleo do risco de integridade. | K10: Reportagem aponta suposto conflito de interesse entre executivo da concessionária e fornecedor contratado. | L10: Exemplo típico (premissa Peers)
A11: 10 | B11: 1. Governança | C11: Integridade | D11: Investigações e Acordo | E11: Credibilidade | F11: Riscos Geopolíticos e Estratégicos | G11: Práticas Ilegais ou Antiéticas | H11: Alto | I11: Contingências e Provisões | J11: Investigação formal, delação e acordo de leniência. O desdobramento financeiro aparece em provisão. | K11: Ministério Público instaura inquérito sobre contratação de obra em SPE do grupo. | L11: Exemplo típico (premissa Peers)
A12: 11 | B12: 1. Governança | C12: Integridade | D12: Controles internos / Prevenção à fraude e corrupção | E12: Credibilidade | F12: Riscos Geopolíticos e Estratégicos | G12: Práticas Ilegais ou Antiéticas | H12: Alto | I12: Integridade das Demonstrações Financeiras | J12: Falha de controle interno é a causa-raiz típica do evento de integridade. | K12: Auditoria interna identifica fraude em processo de compras e o caso chega à imprensa antes do comunicado da empresa. | L12: Exemplo típico (premissa Peers)
A13: 12 | B13: 1. Governança | C13: Integridade | D13: Demonstrações de resultados e auditoria | E13: Credibilidade | F13: Riscos com Finanças e Contabilidade | G13: Integridade das Demonstrações Financeiras | H13: Moderado | I13: Integridade das Informações ao Mercado | J13: Ressalva de auditoria e republicação de demonstração atacam diretamente a integridade contábil. | K13: Auditoria externa emite ressalva sobre reconhecimento de receita nas demonstrações do grupo. | L13: Exemplo típico (premissa Peers)
A14: 13 | B14: 1. Governança | C14: Modelo de negócio | D14: Modelo Operacional Aegea | E14: Credibilidade | F14: — | G14: Sem enquadramento | H14: — | J14: Narrativa de posicionamento institucional. Sem risco corporativo equivalente na matriz. | K14: Não se aplica. Crítica ao modelo privado de operação é registrada em Debate público versus privado. | L14: —
A15: 14 | B15: 1. Governança | C15: Político-institucional | D15: Políticas públicas e setoriais | E15: Credibilidade | F15: Riscos Geopolíticos e Estratégicos | G15: Instabilidade Política / Econômica | H15: Moderado | I15: Relações Institucionais e Governamentais | J15: Mudança de política setorial altera as regras do negócio e tem origem política, não operacional. | K15: Governo federal sinaliza mudança na regra de financiamento do saneamento e analistas apontam efeito sobre concessionárias privadas. | L15: Exemplo típico (premissa Peers)
A16: 15 | B16: 1. Governança | C16: Político-institucional | D16: Patrocínios institucionais | E16: Credibilidade | F16: Riscos Geopolíticos e Estratégicos | G16: Relações Institucionais e Governamentais | H16: Moderado | I16: Práticas Ilegais ou Antiéticas | J16: Patrocínio a ente público, evento ou veículo. Risco residual de leitura como influência indevida. | K16: Patrocínio de festival, carnaval e réveillon citado em veículos locais, incluindo agradecimento de locutor de rádio pelo apoio ao programa. Trinta e três ocorrências no lote auditado de janeiro. | L16: Base jan/2026 (Clipei)
A17: 16 | B17: 1. Governança | C17: Político-institucional | D17: Debate público versus privado | E17: Credibilidade | F17: Riscos Geopolíticos e Estratégicos | G17: Instabilidade Política / Econômica | H17: Moderado | I17: Relações com as Comunidades | J17: Debate ideológico sobre privatização do saneamento. Vetor político, com repercussão comunitária. | K17: Artigo de opinião defende reestatização do serviço e cita a concessionária como exemplo de fracasso da concessão. | L17: Exemplo típico (premissa Peers)
A18: 17 | B18: 1. Governança | C18: Político-institucional | D18: Judicialização e CPIs | E18: Credibilidade | F18: Riscos Geopolíticos e Estratégicos | G18: Legal e Regulatório | H18: Moderado | I18: Relações Institucionais e Governamentais | J18: CPI e ação judicial contra a concessão são instrumento jurídico com motor político. | K18: Câmara municipal aprova abertura de CPI para investigar a execução do contrato de concessão. | L18: Exemplo típico (premissa Peers)
A19: 18 | B19: 1. Governança | C19: Político-institucional | D19: Marco Legal do Saneamento | F19: Riscos Geopolíticos e Estratégicos | G19: Instabilidade Política / Econômica | H19: Moderado | I19: Legal e Regulatório | J19: Alteração do marco é decisão do Legislativo. Vira risco legal quando a norma já está vigente e passa a obrigar. | K19: Proposta em tramitação no Congresso flexibiliza metas do Marco Legal e reportagem cita a concessionária entre as afetadas. | L19: Exemplo típico (premissa Peers)
A20: 19 | B20: 1. Governança | C20: Contratos e Regulação | D20: Agências reguladoras | F20: Riscos Geopolíticos e Estratégicos | G20: Relações Institucionais e Governamentais | H20: Moderado | I20: Legal e Regulatório | J20: Subtema de relacionamento institucional. O ato sancionatório do regulador fica em Fiscalização regulatória, para não duplicar. | K20: Troca da diretoria da agência reguladora estadual é noticiada com menção às concessões sob fiscalização. | L20: Exemplo típico (premissa Peers)
A21: 20 | B21: 1. Governança | C21: Político-institucional | D21: Agenda Associações (Políticas setoriais) | E21: Credibilidade | F21: Riscos Geopolíticos e Estratégicos | G21: Relações Institucionais e Governamentais | H21: Moderado | I21: Instabilidade Política / Econômica | J21: Atuação associativa é posicionamento setorial coletivo. Risco de leitura como defesa de interesse contra o usuário. | K21: Associação setorial divulga nota contra mudança na regra tarifária e é acusada de representar interesse das concessionárias. | L21: Exemplo típico (premissa Peers)
A22: 21 | B22: 2. Eficiência Operacional e Qualidade | C22: Abastecimento de água | D22: Frequência, Continuidade | E22: Legitimidade | F22: Riscos Operacionais | G22: Entrega de água e tratamento de esgoto | H22: Critico | I22: Relações com as Comunidades | J22: Falta de água é o fato reputacional mais recorrente do setor e aciona diretamente o risco Crítico de entrega. | K22: Falta de água em bairros atendidos pela concessionária, com reclamação de moradores em veículo local. Na base de janeiro, parte desses registros estava rotulada pela clipadora como fato relevante. | L22: Base jan/2026 (Clipei)
A23: 22 | B23: 2. Eficiência Operacional e Qualidade | C23: Abastecimento de água | D23: Perdas, fraudes, furtos e ligações irregulares | E23: Legitimidade | F23: Riscos Operacionais | G23: Integridade e Confiabilidade dos Ativos | H23: Alto | I23: Gestão ESG e Sustentabilidade | J23: Índice de perdas e furto são lidos como falha de confiabilidade do ativo e como desperdício de recurso natural. | K23: Furto de hidrômetro em bairro, registro presente na base de janeiro e também rotulado como fato relevante. | L23: Base jan/2026 (Clipei)
A24: 23 | B24: 2. Eficiência Operacional e Qualidade | C24: Abastecimento de água | D24: Rompimento de adutora | E24: Legitimidade | F24: Riscos Operacionais | G24: Integridade e Confiabilidade dos Ativos | H24: Alto | I24: Entrega de água e tratamento de esgoto | J24: Falha estrutural de ativo crítico, com desabastecimento e dano a terceiro ao mesmo tempo. | K24: Rompimento de adutora deixa municípios sem água e provoca alagamento em via pública. | L24: Exemplo típico (premissa Peers)
A25: 24 | B25: 2. Eficiência Operacional e Qualidade | C25: Abastecimento de água | D25: Plano de contingência e redundância | E25: Legitimidade | F25: Riscos com Stakeholders e novos negócios | G25: Gestão de Crises | H25: Critico | I25: Integridade e Confiabilidade dos Ativos | J25: Único subtema que endereça diretamente o cluster de Gestão de Crises, que é Crítico. Ver aba Pontos de atenção. | K25: Após mais de 48 horas de desabastecimento, a imprensa questiona a existência e a efetividade do plano de contingência da concessionária. | L25: Exemplo típico (premissa Peers)
A26: 25 | B26: 2. Eficiência Operacional e Qualidade | C26: Qualidade da água | D26: Gestão da qualidade da água | E26: Legitimidade | F26: Riscos Operacionais | G26: Entrega de água e tratamento de esgoto | H26: Critico | I26: Saúde e Segurança | J26: Qualidade da água combina saúde pública e prova técnica. Severidade máxima na entrega. | K26: Laudo de vigilância sanitária aponta água fora do padrão de potabilidade em ponto da rede de distribuição. | L26: Exemplo típico (premissa Peers)
A27: 26 | B27: 2. Eficiência Operacional e Qualidade | C27: Qualidade da água | D27: Monitoramento e controle de qualidade da água | E27: Legitimidade | F27: Riscos Operacionais | G27: Entrega de água e tratamento de esgoto | H27: Critico | I27: Gestão de Licenças | J27: Falha ou atraso na divulgação converte evento técnico em suspeita de ocultação de informação. | K27: Reportagem aponta atraso na publicação dos resultados de análise de qualidade da água exigidos por norma. | L27: Exemplo típico (premissa Peers)
A28: 27 | B28: 2. Eficiência Operacional e Qualidade | C28: Qualidade da água | D28: Potabilidade | E28: Legitimidade | F28: Riscos Operacionais | G28: Entrega de água e tratamento de esgoto | H28: Critico | I28: Saúde e Segurança | J28: Aciona vigilância sanitária e tem potencial de dano irreversível à licença social de operar. | K28: Moradores relatam água turva e com odor; vigilância sanitária coleta amostras e o caso vira pauta regional. | L28: Exemplo típico (premissa Peers)
A29: 28 | B29: 2. Eficiência Operacional e Qualidade | C29: Esgoto | D29: Rede e Coleta de esgoto | E29: Legitimidade | F29: Riscos Operacionais | G29: Entrega de água e tratamento de esgoto | H29: Critico | I29: Relações com as Comunidades | J29: Cobertura e falha de coleta são o núcleo do risco Crítico de entrega. | K29: Bairro segue sem rede de esgoto apesar da meta contratual e moradores cobram a concessionária em audiência pública. | L29: Exemplo típico (premissa Peers)
A30: 29 | B30: 2. Eficiência Operacional e Qualidade | C30: Esgoto | D30: Tratamento de esgoto | E30: Legitimidade | F30: Riscos Operacionais | G30: Entrega de água e tratamento de esgoto | H30: Critico | I30: Meio ambiente operacional | J30: Tratamento inadequado é simultaneamente falha de entrega e poluição. | K30: Estação de tratamento opera abaixo da capacidade e esgoto sem tratamento chega a corpo hídrico. | L30: Exemplo típico (premissa Peers)
A31: 30 | B31: 2. Eficiência Operacional e Qualidade | C31: Esgoto | D31: Lançamento irregular e extravasamento | E31: Legitimidade | F31: Riscos Operacionais | G31: Meio ambiente operacional | H31: Alto | I31: Gestão de Licenças | J31: Poluição local com autuação ambiental provável. O dano é ambiental antes de ser de serviço. | K31: Extravasamento de esgoto em via pública gera autuação do órgão ambiental estadual. | L31: Exemplo típico (premissa Peers)
A32: 31 | B32: 2. Eficiência Operacional e Qualidade | C32: Esgoto | D32: Balneabilidade | E32: Legitimidade | F32: Riscos Operacionais | G32: Meio ambiente operacional | H32: Alto | I32: Relações com as Comunidades | J32: Impacto ambiental visível e de apelo público alto, em especial no litoral. | K32: Boletim de balneabilidade da Fepam replicado por dezenas de portais do Rio Grande do Sul. Maior bloco unitário do lote auditado de janeiro, 50 títulos, hoje rotulados como licença ambiental. | L32: Base jan/2026 (Clipei)
A33: 32 | B33: 2. Eficiência Operacional e Qualidade | C33: Esgoto | D33: Odor e incômodo | F33: Riscos ESG | G33: Relações com as Comunidades | H33: Alto | I33: Meio ambiente operacional | J33: Incômodo de vizinhança. O dano se materializa na relação com a comunidade do entorno. | K33: Moradores do entorno de estação elevatória reclamam de mau cheiro recorrente e acionam a prefeitura. | L33: Exemplo típico (premissa Peers)
A34: 33 | B34: 2. Eficiência Operacional e Qualidade | C34: Obras e intervenções | D34: Custos e eficiência | E34: Credibilidade | F34: Riscos em Investimentos de Capital | G34: Gestão de Contratos e Terceiros | H34: Moderado | I34: Gestão de Portfólio e Estrutura de Capital | J34: Desvio de custo e de prazo de obra remete à gestão de contratos e de terceiros. | K34: Tribunal de contas aponta sobrepreço e atraso em obra de saneamento executada por terceiro contratado. | L34: Exemplo típico (premissa Peers)
A35: 34 | B35: 2. Eficiência Operacional e Qualidade | C35: Obras e intervenções | D35: Acidentes e danos a terceiros | E35: Credibilidade | F35: Riscos Operacionais | G35: Saúde e Segurança | H35: Alto | I35: Gestão de Contratos e Terceiros | J35: Acidente em obra com vítima ou dano patrimonial a terceiro é evento de saúde e segurança. | K35: Vala de obra sem sinalização provoca acidente com motociclista; o serviço era executado por empresa terceirizada. | L35: Exemplo típico (premissa Peers)
A36: 35 | B36: 2. Eficiência Operacional e Qualidade | C36: Obras e intervenções | D36: Expansão da rede | E36: Credibilidade | F36: Riscos em Investimentos de Capital | G36: Gestão de Contratos e Terceiros | H36: Moderado | I36: Gestão Ambiental em Projetos e Obras | J36: Execução de capex. Atraso de expansão também tem leitura de meta contratual. | K36: Cronograma de expansão da rede não é cumprido e a prefeitura cobra a concessionária publicamente. | L36: Exemplo típico (premissa Peers)
A37: 36 | B37: 2. Eficiência Operacional e Qualidade | C37: Obras e intervenções | D37: Pavimentação e recomposição | E37: Credibilidade | F37: Riscos em Investimentos de Capital | G37: Gestão de Contratos e Terceiros | H37: Moderado | I37: Relações com as Comunidades | J37: Falha de recomposição é a reclamação de obra mais frequente e costuma ser responsabilidade do terceiro executor. | K37: Buracos deixados após obra da concessionária permanecem meses sem recomposição e viram pauta de veículo local. | L37: Exemplo típico (premissa Peers)
A38: 37 | B38: 2. Eficiência Operacional e Qualidade | C38: Obras e intervenções | D38: Manutenção, interdições e transtornos urbanos | E38: Credibilidade | F38: Riscos ESG | G38: Relações com as Comunidades | H38: Alto | I38: Gestão de Contratos e Terceiros | J38: Transtorno urbano é o canal direto de deterioração da relação com a comunidade. | K38: Interdição de avenida para manutenção de rede gera congestionamento e reclamação de comerciantes. | L38: Exemplo típico (premissa Peers)
A39: 38 | B39: 2. Eficiência Operacional e Qualidade | C39: Atendimento ao cliente | D39: Canais de atendimento | E39: Credibilidade | F39: Riscos com Clientes | G39: Regularidade, Atendimento e Satisfação | H39: Alto | J39: Disponibilidade e tempo de resposta dos canais. Dano registrado no risco com clientes. | K39: Reportagem mostra tempo de espera no call center durante episódio de falta de água. | L39: Exemplo típico (premissa Peers)
A40: 39 | B40: 2. Eficiência Operacional e Qualidade | C40: Atendimento ao cliente | D40: Atendimento ao cliente | E40: Credibilidade | F40: Riscos com Clientes | G40: Regularidade, Atendimento e Satisfação | H40: Alto | J40: Qualidade e resolutividade do atendimento prestado. | K40: Cliente relata três meses sem solução para vazamento na calçada, mesmo com protocolo aberto. | L40: Exemplo típico (premissa Peers)
...

Sheet Taxonomia de temas
A1: Nível 1: Pilar reputacional | B1: Nível 2: Tema estratégico | C1: Nível 3: Subtema | D1: LSO | E1: Risk tracking | F1: Issue RepRisk correspondente | G1: Detalhamento | H1: Pauta | I1: Campo de classificação da empresa | J1: To do Comunicação
A2: 1. Governança | B2: Governança corporativa | C2: Estrutura de governança / Conselho e comitês | D2: Credibilidade | E2: Sem enquadramento | H2: Espontânea | I2: Concorrentes | J2: Definição de porta-vozes
A3: 1. Governança | B3: Governança corporativa | C3: Acionistas | D3: Credibilidade | E3: Gestão de Portfólio e Estrutura de Capital | H3: Produzida | I3: Unidades Aegea | J3: Preenchimento planilha
A4: 1. Governança | B4: Contratos e Regulação | C4: Cumprimento contratual | D4: Legitimidade | E4: Legal e Regulatório | H4: Provocada | J4: Validar taxonomia
A5: 1. Governança | B5: Contratos e Regulação | C5: Revisão e renovação de contratos | D5: Legitimidade | E5: Legal e Regulatório | H5: Publicidade | J5: Usuários
A6: 1. Governança | B6: Contratos e Regulação | C6: Reequilíbrio econômico-financeiro | D6: Legitimidade | E6: Legal e Regulatório | J6: Reprisk
A7: 1. Governança | B7: Contratos e Regulação | C7: Segurança jurídica | D7: Legitimidade | E7: Legal e Regulatório | J7: Porta vozes
A8: 1. Governança | B8: Contratos e Regulação | C8: Fiscalização regulatória | D8: Legitimidade | E8: Legal e Regulatório
A9: 1. Governança | B9: Contratos e Regulação | C9: Multa e processos | D9: Credibilidade | E9: Contingências e Provisões
A10: 1. Governança | B10: Integridade | C10: Ética e conduta | D10: Credibilidade | E10: Práticas Ilegais ou Antiéticas
A11: 1. Governança | B11: Integridade | C11: Investigações e Acordo | D11: Credibilidade | E11: Práticas Ilegais ou Antiéticas
A12: 1. Governança | B12: Integridade | C12: Controles internos / Prevenção à fraude e corrupção | D12: Credibilidade | E12: Práticas Ilegais ou Antiéticas
A13: 1. Governança | B13: Integridade | C13: Demonstrações de resultados e auditoria | D13: Credibilidade | E13: Integridade das Demonstrações Financeiras
A14: 1. Governança | B14: Modelo de negócio | C14: Modelo Operacional Aegea | D14: Credibilidade | E14: Sem enquadramento
A15: 1. Governança | B15: Político-institucional | C15: Políticas públicas e setoriais | D15: Credibilidade | E15: Instabilidade Política / Econômica
A16: 1. Governança | B16: Político-institucional | C16: Patrocínios institucionais | D16: Credibilidade | E16: Relações Institucionais e Governamentais
A17: 1. Governança | B17: Político-institucional | C17: Debate público versus privado | D17: Credibilidade | E17: Instabilidade Política / Econômica
A18: 1. Governança | B18: Político-institucional | C18: Judicialização e CPIs | D18: Credibilidade | E18: Legal e Regulatório
A19: 1. Governança | B19: Político-institucional | C19: Marco Legal do Saneamento | E19: Instabilidade Política / Econômica
A20: 1. Governança | B20: Contratos e Regulação | C20: Agências reguladoras | E20: Relações Institucionais e Governamentais
A21: 1. Governança | B21: Político-institucional | C21: Agenda Associações (Políticas setoriais) | D21: Credibilidade | E21: Relações Institucionais e Governamentais
A22: 2. Eficiência Operacional e Qualidade | B22: Abastecimento de água | C22: Frequência, Continuidade | D22: Legitimidade | E22: Entrega de água e tratamento de esgoto
A23: 2. Eficiência Operacional e Qualidade | B23: Abastecimento de água | C23: Perdas, fraudes, furtos e ligações irregulares | D23: Legitimidade | E23: Integridade e Confiabilidade dos Ativos
A24: 2. Eficiência Operacional e Qualidade | B24: Abastecimento de água | C24: Rompimento de adutora | D24: Legitimidade | E24: Integridade e Confiabilidade dos Ativos
A25: 2. Eficiência Operacional e Qualidade | B25: Abastecimento de água | C25: Plano de contingência e redundância | D25: Legitimidade | E25: Gestão de Crises
A26: 2. Eficiência Operacional e Qualidade | B26: Qualidade da água | C26: Gestão da qualidade da água | D26: Legitimidade | E26: Entrega de água e tratamento de esgoto
A27: 2. Eficiência Operacional e Qualidade | B27: Qualidade da água | C27: Monitoramento e controle de qualidade da água | D27: Legitimidade | E27: Entrega de água e tratamento de esgoto
A28: 2. Eficiência Operacional e Qualidade | B28: Qualidade da água | C28: Potabilidade | D28: Legitimidade | E28: Entrega de água e tratamento de esgoto
A29: 2. Eficiência Operacional e Qualidade | B29: Esgoto | C29: Rede e Coleta de esgoto | D29: Legitimidade | E29: Entrega de água e tratamento de esgoto
A30: 2. Eficiência Operacional e Qualidade | B30: Esgoto | C30: Tratamento de esgoto | D30: Legitimidade | E30: Entrega de água e tratamento de esgoto
A31: 2. Eficiência Operacional e Qualidade | B31: Esgoto | C31: Lançamento irregular e extravasamento | D31: Legitimidade | E31: Meio ambiente operacional
A32: 2. Eficiência Operacional e Qualidade | B32: Esgoto | C32: Balneabilidade | D32: Legitimidade | E32: Meio ambiente operacional
A33: 2. Eficiência Operacional e Qualidade | B33: Esgoto | C33: Odor e incômodo | E33: Relações com as Comunidades
A34: 2. Eficiência Operacional e Qualidade | B34: Obras e intervenções | C34: Custos e eficiência | D34: Credibilidade | E34: Gestão de Contratos e Terceiros
A35: 2. Eficiência Operacional e Qualidade | B35: Obras e intervenções | C35: Acidentes e danos a terceiros | D35: Credibilidade | E35: Saúde e Segurança
A36: 2. Eficiência Operacional e Qualidade | B36: Obras e intervenções | C36: Expansão da rede | D36: Credibilidade | E36: Gestão de Contratos e Terceiros
A37: 2. Eficiência Operacional e Qualidade | B37: Obras e intervenções | C37: Pavimentação e recomposição | D37: Credibilidade | E37: Gestão de Contratos e Terceiros
A38: 2. Eficiência Operacional e Qualidade | B38: Obras e intervenções | C38: Manutenção, interdições e transtornos urbanos | D38: Credibilidade | E38: Relações com as Comunidades
A39: 2. Eficiência Operacional e Qualidade | B39: Atendimento ao cliente | C39: Canais de atendimento | D39: Credibilidade | E39: Regularidade, Atendimento e Satisfação
A40: 2. Eficiência Operacional e Qualidade | B40: Atendimento ao cliente | C40: Atendimento ao cliente | D40: Credibilidade | E40: Regularidade, Atendimento e Satisfação
...

Sheet Risk tracking map
A1: Risk Cluster | B1: Risk | C1: Severity | D1: Subtemas atribuídos (primário) | E1: Subtemas atribuídos (secundário)
A2: Riscos Geopolíticos e Estratégicos | B2: Instabilidade Política / Econômica | C2: Moderado | D2: =COUNTIF('De-para Risk tracking'!$G$2:$G$105,$B2) -> 3 | E2: =COUNTIF('De-para Risk tracking'!$I$2:$I$105,$B2) -> 3
A3: Riscos Geopolíticos e Estratégicos | B3: Relações Institucionais e Governamentais | C3: Moderado | D3: =COUNTIF('De-para Risk tracking'!$G$2:$G$105,$B3) -> 3 | E3: =COUNTIF('De-para Risk tracking'!$I$2:$I$105,$B3) -> 3
A4: Riscos Geopolíticos e Estratégicos | B4: Gestão de Portfólio e Estrutura de Capital | C4: Alto | D4: =COUNTIF('De-para Risk tracking'!$G$2:$G$105,$B4) -> 6 | E4: =COUNTIF('De-para Risk tracking'!$I$2:$I$105,$B4) -> 4
A5: Riscos Geopolíticos e Estratégicos | B5: Liquidez, Gestão da Dívida e Quebra de Covenants de financiamentos | C5: Alto | D5: =COUNTIF('De-para Risk tracking'!$G$2:$G$105,$B5) -> 4 | E5: =COUNTIF('De-para Risk tracking'!$I$2:$I$105,$B5) -> 3
A6: Riscos Geopolíticos e Estratégicos | B6: Legal e Regulatório | C6: Moderado | D6: =COUNTIF('De-para Risk tracking'!$G$2:$G$105,$B6) -> 9 | E6: =COUNTIF('De-para Risk tracking'!$I$2:$I$105,$B6) -> 5
A7: Riscos Geopolíticos e Estratégicos | B7: Práticas Ilegais ou Antiéticas | C7: Alto | D7: =COUNTIF('De-para Risk tracking'!$G$2:$G$105,$B7) -> 3 | E7: =COUNTIF('De-para Risk tracking'!$I$2:$I$105,$B7) -> 3
A8: Riscos Geopolíticos e Estratégicos | B8: Gestão do Capital Humano | C8: Moderado | D8: =COUNTIF('De-para Risk tracking'!$G$2:$G$105,$B8) -> 5 | E8: =COUNTIF('De-para Risk tracking'!$I$2:$I$105,$B8) -> 2
A9: Riscos em Investimentos de Capital | B9: Gestão de Contratos e Terceiros | C9: Moderado | D9: =COUNTIF('De-para Risk tracking'!$G$2:$G$105,$B9) -> 5 | E9: =COUNTIF('De-para Risk tracking'!$I$2:$I$105,$B9) -> 5
A10: Riscos em Investimentos de Capital | B10: Adoção e Efetividade de Novas Tecnologias | C10: Alto | D10: =COUNTIF('De-para Risk tracking'!$G$2:$G$105,$B10) -> 5 | E10: =COUNTIF('De-para Risk tracking'!$I$2:$I$105,$B10) -> 3
A11: Riscos em Investimentos de Capital | B11: Gestão Ambiental em Projetos e Obras | C11: Alto | D11: =COUNTIF('De-para Risk tracking'!$G$2:$G$105,$B11) -> 1 | E11: =COUNTIF('De-para Risk tracking'!$I$2:$I$105,$B11) -> 1
A12: Riscos Operacionais | B12: Gestão de Insumos | C12: Moderado | D12: =COUNTIF('De-para Risk tracking'!$G$2:$G$105,$B12) -> 1 | E12: =COUNTIF('De-para Risk tracking'!$I$2:$I$105,$B12) -> 0
A13: Riscos Operacionais | B13: Gestão de Licenças | C13: Alto | D13: =COUNTIF('De-para Risk tracking'!$G$2:$G$105,$B13) -> 1 | E13: =COUNTIF('De-para Risk tracking'!$I$2:$I$105,$B13) -> 2
... A33: Riscos com Stakeholders e novos negócios | B33: Novas Tendências e Futuro | C33: Moderado | D33: =COUNTIF('De-para Risk tracking'!$G$2:$G$105,$B33) -> 4 | E33: =COUNTIF('De-para Risk tracking'!$I$2:$I$105,$B33) -> 1

Sheet Pontos de atenção
A1: # | B1: Tipo | C1: Ponto | D1: Evidência | E1: Criticidade | F1: Recomendação
A2: 1 | B2: Taxonomia | C2: Segurança da informação é um subtema para três riscos | D2: Cybersecurity é Crítico, Proteção de Dados é Alto e LGPD é Moderado. A taxonomia funde os três em um subtema só. | E2: Alta | F2: Desdobrar em três subtemas antes do sign-off. Enquanto estiver fundido, o painel não separa o risco Crítico do Moderado, e Proteção de Dados e LGPD ficam com zero subtema primário.
A3: 2 | B3: Método | C3: Gestão de Crises recebe um único subtema | D3: Risco Crítico atendido apenas por Plano de contingência e redundância. Crise atravessa os outros 31 riscos. | E3: Alta | F3: Tratar crise como atributo do evento, não como destino de subtema. Caso contrário o risco mais severo fica subdimensionado no painel.
A4: 3 | B4: Concentração | C4: Legal e Regulatório concentra o maior número de subtemas e é Moderado | D4: Nove subtemas apontam para um risco de severidade média. É a maior concentração da taxonomia. | E4: Alta | F4: Checar com Riscos. Ou a taxonomia superdimensiona o eixo regulatório, ou a matriz subdimensiona o risco. O painel vai gerar alerta de volume alto num risco de segunda ordem.
A5: 4 | B5: Lacuna | C5: Integridade estrutural de ativo crítico | D5: Integridade e Confiabilidade dos Ativos é Alto e não tem subtema cobrindo integridade de barragem ou reservatório. | E5: Alta | F5: Criar subtema sob Eficiência Operacional, conectado a Eventos Climáticos.
A6: 5 | B6: Lacuna | C6: Produtos químicos de tratamento | D6: Gestão de Insumos ficou com um único subtema, energia. O insumo de maior criticidade operacional do setor não existe na taxonomia. | E6: Média | F6: Criar subtema de insumos de tratamento sob Eficiência Operacional.
A7: 6 | B7: Lacuna | C7: Conduta concorrencial | D7: Nenhum subtema dedicado. O ponto mais próximo é Novos Negócios e Leilões. | E7: Alta | F7: Criar subtema sob Integridade ou ampliar o escopo de Novos Negócios e Leilões.
A8: 7 | B8: Cobertura | C8: Cobertura de Seguros fica sem nenhum subtema | D8: Risco Moderado sem expressão pública, salvo em sinistro de grande porte. | E8: Baixa | F8: Registrar a ausência como decisão consciente, para não parecer falha de mapeamento.
A9: 8 | B9: Escopo | C9: Drenagem urbana sem dono na matriz | D9: Fora do escopo contratual na maior parte das concessões, mas o alagamento é atribuído à Aegea. | E9: Média | F9: Tratar como risco de atribuição indevida, com resposta preparada. Não forçar enquadramento.
A10: 9 | B10: Dado | C10: Exemplos de notícia sem lastro completo na base | D10: Cinco linhas têm exemplo observado na base de janeiro. As demais usam formulação típica, porque a base não está reclassificada nos 104 subtemas. | E10: Média | F10: Reclassificar a amostra de janeiro nos 104 subtemas e substituir os exemplos típicos por títulos reais antes de publicar o material.
A11: 10 | B11: Validação | C11: Atribuição não validada com a área de Riscos | D11: As 104 linhas são premissa Peers. A severidade é do cliente, a atribuição não. | E11: Alta | F11: Rodar a validação com Riscos antes do sign-off. Colunas M e N da aba De-para.
